<?xml version="1.0" ?>
<robot name="robocluedo_robot" xmlns:xacro="http://www.ros.org/wiki/xacro">
    
    <link name="arm_base_link">
        
		<inertial>
            <mass value="0.1" />
            <origin rpy="0 0 0" xyz="0 0 0" />
            <inertia ixx="0.0000416666667" ixy="0" ixz="0" iyy="0.0000416666667" iyz="0" izz="0.0000416666667" />
        </inertial>

        <collision>
            <origin rpy="0 0 0" xyz="0 0 0" />
            <geometry>
                <box size="0.1 0.1 0.15" />
            </geometry>
        </collision>
        <visual>
            <origin rpy="0 0 0" xyz="0 0 0" />
            <geometry>
                <box size="0.1 0.1 0.2" />
            </geometry>
            <material name="white" />
        </visual>
    </link>
    
    <joint name="arm_base_to_base" type="fixed">
        <origin rpy="0 0 0" xyz="-0.075 0 0.085" />
        <parent link="base_link" />
        <child link="arm_base_link" />
    </joint>
    
    <link name="arm_link_01">
        
		<inertial>
            <mass value="0.025" />
            <origin rpy="0 0 0" xyz="0 0 0.15" />
            <inertia ixx="0.000010279" ixy="0" ixz="0" iyy="0.000010279" iyz="0" izz="0.000007225" />
        </inertial>

        <collision>
            <origin rpy="0 0 0" xyz="0 0 0.15" />
            <geometry>
                <cylinder length="0.3" radius="0.04" />
            </geometry>
        </collision>
        <visual>
            <origin rpy="0 0 0" xyz="0 0 0.15" />
            <geometry>
                <cylinder length="0.3" radius="0.04" />
            </geometry>
            <material name="red" />
        </visual>
    </link>
    
    <joint name="arm_joint_01" type="revolute">
        <axis xyz="0 0 1" />
        <limit effort="1000.0" lower="-3.14" upper="3.14" velocity="0.2" />
        <origin rpy="0 0 0" xyz="0 0 0.04999999999999999" />
        <parent link="arm_base_link" />
        <child link="arm_link_01" />
    </joint>
    
    <link name="arm_link_02">
        
<inertial>
            <mass value="0.025" />
            <origin rpy="0 0 0" xyz="0 0 0.15" />
            <inertia ixx="0.000010279" ixy="0" ixz="0" iyy="0.000010279" iyz="0" izz="0.000007225" />
        </inertial>

        <collision>
            <origin rpy="0 0 0" xyz="0 0 0.15" />
            <geometry>
                <cylinder length="0.3" radius="0.04" />
            </geometry>
        </collision>
        <visual>
            <origin rpy="0 0 0" xyz="0 0 0.15" />
            <geometry>
                <cylinder length="0.3" radius="0.04" />
            </geometry>
            <material name="red" />
        </visual>
    </link>
    
    <joint name="arm_joint_02" type="revolute">
        <axis xyz="1 0 0" />
        <limit effort="1000.0" lower="-1.8" upper="1.8" velocity="0.2" />
        <origin rpy="0 0 0" xyz="0 0 0.3" />
        <parent link="arm_link_01" />
        <child link="arm_link_02" />
    </joint>
    
    <link name="arm_link_03">
        
<inertial>
            <mass value="0.025" />
            <origin rpy="0 0 0" xyz="0 0 0.15" />
            <inertia ixx="0.000010279" ixy="0" ixz="0" iyy="0.000010279" iyz="0" izz="0.000007225" />
        </inertial>

        <collision>
            <origin rpy="0 0 0" xyz="0 0 0.15" />
            <geometry>
                <cylinder length="0.3" radius="0.04" />
            </geometry>
        </collision>
        <visual>
            <origin rpy="0 0 0" xyz="0 0 0.15" />
            <geometry>
                <cylinder length="0.3" radius="0.04" />
            </geometry>
            <material name="red" />
        </visual>
    </link>
    
    <joint name="arm_joint_03" type="revolute">
        <axis xyz="1 0 0" />
        <limit effort="1000.0" lower="-1.8" upper="1.8" velocity="0.2" />
        <origin rpy="0 0 0" xyz="0 0 0.3" />
        <parent link="arm_link_02" />
        <child link="arm_link_03" />
    </joint>
    

    
</robot>
